Workbook
Name InitialCapital: '01_Settings'!$B$6
Name BEThreshold: '01_Settings'!$B$9
Name AccountCurrency: '01_Settings'!$B$7
Name ListPairs: 99_Lists!$A$2:$A$30
Name ListSetups: 99_Lists!$B$2:$B$5
Name ListSessions: 99_Lists!$C$2:$C$5
Name ListPositions: 99_Lists!$D$2:$D$3
Name ListPlan: 99_Lists!$E$2:$E$4
Name ListExitReason: 99_Lists!$F$2:$F$7
Name ListMarket: 99_Lists!$G$2:$G$5
Name FilterPairs: 99_Lists!$I$2:$I$31
Name FilterDays: 99_Lists!$J$2:$J$9
Name FilterSessions: 99_Lists!$K$2:$K$6
Name FilterSetups: 99_Lists!$L$2:$L$6
Name F_Pair: '03_Dashboard'!$B$6
Name F_Day: '03_Dashboard'!$D$6
Name F_Session: '03_Dashboard'!$F$6
Name F_Setup: '03_Dashboard'!$H$6
Name F_From: '03_Dashboard'!$J$6
Name F_To: '03_Dashboard'!$L$6

Sheet 00_ReadMe
A1: AURUM LEDGER
A2: Professional forex trading journal · Excel companion to the Aurum desk
A4: HOW TO START
A5: 1. Open 01_Settings. Type your initial capital in the yellow cell B6. Set currency and breakeven threshold.
A6: 2. Go to 02_Trade_Log. Starting at row 2, fill only the yellow cells. Grey cells calculate themselves.
A7: 3. Leave Exit price and Exit date empty while the trade is open. Fill them when it closes. Paste broker PnL into “PnL override” for crosses.
A8: 4. Read 03_Dashboard. Use the yellow dropdowns (pair, weekday, session, setup, dates) to slice performance.
A9: 5. Read 04_Breakdowns for the full tables (pair / day / session / setup) with win rate, PnL, profit factor, averages.
A11: YELLOW = YOU TYPE. GREY = FORMULA. Do not overwrite grey cells. Adding a new row: copy the entire row 2 formulas down, or type in the next empty yellow row (formulas are pre-filled through row 401).
A13: COLUMN MAP — TRADE LOG
A14: Basic: S/N (auto), Day of week (auto), Entry date, Entry time, Pair, Position, Session, Lot size, Risk amount, Risk %.
A15: Management: Entry, Stop loss, Take profit, Setup.
... A50: Initial capital, account currency, commission/swap, broker PnL override, open vs closed, pips, planned vs realized RR, exit reason, plan adherence, market condition, ticket, risk %, expectancy, profit-factor zero-loss guard.

Sheet 01_Settings
A1: AURUM LEDGER
A2: Account settings · initial capital lives here · every formula starts from this sheet
A4: INPUTS (yellow cells)
A5: Account name | C5: Optional label (broker / challenge / live).
A6: Initial capital | B6: 10000 | C6: Starting cash. Equity curve begins at this number.
A7: Account currency | B7: USD | C7: Used for number formats and the dashboard.
A8: Default risk % | B8: 1 | C8: Informational default for the Risk % column.
A9: Breakeven threshold | B9: 0.5 | C9: |Net PnL| at or below this is BE, not a win or a loss.
A11: CALCULATED
A12: Closed trades | B12: =COUNTIF('02_Trade_Log'!AK:AK,"Win")+COUNTIF('02_Trade_Log'!AK:AK,"Loss")+COUNTIF('02_Trade_Log'!AK:AK,"BE")
A13: Open trades | B13: =COUNTIF('02_Trade_Log'!AK:AK,"Open")
A14: Total net PnL | B14: =SUMIF('02_Trade_Log'!AK:AK,"<>Open",'02_Trade_Log'!AJ:AJ)
A15: Current equity | B15: =B6+B14
A16: Wins | B16: =COUNTIF('02_Trade_Log'!AK:AK,"Win")
A17: Losses | B17: =COUNTIF('02_Trade_Log'!AK:AK,"Loss")
A18: Breakevens | B18: =COUNTIF('02_Trade_Log'!AK:AK,"BE")
A19: Win rate | B19: =IF(B12=0,"—",B16/B12)
A20: Gross profit | B20: =SUMIFS('02_Trade_Log'!AJ:AJ,'02_Trade_Log'!AJ:AJ,">0",'02_Trade_Log'!AK:AK,"<>Open")
A21: Gross loss (abs) | B21: =ABS(SUMIFS('02_Trade_Log'!AJ:AJ,'02_Trade_Log'!AJ:AJ,"<0",'02_Trade_Log'!AK:AK,"<>Open"))
A22: Profit factor | B22: =IF(B21=0,IF(B20>0,"∞","—"),B20/B21)
A24: RULES
A25: 1. Yellow cells are the only settings you type. Grey cells are formulas — do not overwrite them.
A26: 2. Enter trades on 02_Trade_Log, starting at row 2. Do not insert columns; adding rows inside the table is safe.
A27: 3. Leave Exit price and Exit date blank while a trade is open. Open trades never change equity, win rate, or profit factor.
A28: 4. If the pair is a non-USD cross, paste the broker PnL into “PnL override”. Estimated PnL for crosses uses ~10 account-units per pip per standard lot.
A29: 5. Pip size: JPY pairs 0.01 · XAUUSD 0.10 · other FX 0.0001. Contract: 100,000 FX · 100 oz gold.
A30: 6. Buy: direction +1. Sell: direction −1. Result pips = (exit − entry) × direction ÷ pip size.
A31: 7. Planned RR = TP pips ÷ SL pips. Realized RR = result pips ÷ SL pips (negative on a loss).
A32: 8. Net PnL = (override if present, else estimate) − commission. BE when |Net PnL| ≤ breakeven threshold.
A33: 9. Profit factor = gross profit ÷ gross loss. If gross loss is 0 and gross profit > 0 the cell shows ∞.
A34: 10. Balance after trade is a running sum in row order. Sort the log by exit date before reading the equity path.
A35: 11. S/N and Day of week are automatic. Dropdowns lock Pair, Position, Session, Setup, Plan, Exit reason, Market.
A36: 12. Example / demo rows are not included. Do not invent results; log only tickets you actually took.

Sheet 02_Trade_Log
A1: S/N | B1: Day of week | C1: Entry date | D1: Entry time | E1: Currency pair | F1: Position | G1: Session | H1: Lot size | I1: Risk per trade | J1: Risk % | K1: Entry price | L1: Stop loss | M1: Take profit | N1: Trading setup | O1: Exit price | P1: Exit date | Q1: Exit time | R1: Commission / swap | S1: PnL override (broker) | T1: Notes | U1: Followed plan | V1: Exit reason | W1: Market condition | X1: Ticket / ID | Y1: Pip size | Z1: Direction | AA1: Contract size | AB1: SL pips | AC1: TP pips | AD1: Result pips | AE1: Planned RR | AF1: Realized RR | AG1: Duration (hours) | AH1: Trade duration | AI1: Estimated PnL | AJ1: Net PnL | AK1: Result | AL1: Balance after trade | AM1: Closed?
A2: =IF(C2="","",COUNTA($C$2:C2)) | B2: =IF(C2="","",TEXT(C2,"dddd")) | Y2: =IF($C2="","",IF(E2="XAUUSD",0.1,IF(ISNUMBER(SEARCH("JPY",E2)),0.01,0.0001))) | Z2: =IF($C2="","",IF(F2="Sell",-1,1)) | AA2: =IF($C2="","",IF(E2="XAUUSD",100,100000)) | AB2: =IF(OR(K2="",L2=""),"",ABS(K2-L2)/Y2) | AC2: =IF(OR(K2="",M2=""),"",ABS(M2-K2)/Y2) | AD2: =IF(OR(K2="",O2=""),"",(O2-K2)*Z2/Y2) | AE2: =IF(OR(AB2="",AB2=0,AC2=""),"",AC2/AB2) | AF2: =IF(OR(AB2="",AB2=0,AD2=""),"",AD2/AB2) | AG2: =IF(OR(C2="",P2=""),"",((P2+IF(Q2="",0,Q2))-(C2+IF(D2="",0,D2)))*24) | AH2: =IF(AG2="","",INT(AG2/24)&"d "&INT(MOD(AG2,24))&"h "&INT(MOD(AG2*60,60))&"m") | AI2: =IF(OR(O2="",K2="",H2=""),"",IF(OR(E2="XAUUSD",RIGHT(E2,3)="USD"),(O2-K2)*Z2*AA2*H2,IF(LEFT(E2,3)="USD",IF(O2=0,"",(O2-K2)*Z2*AA2*H2/O2),AD2*10*H2))) | AJ2: =IF(O2="","",IF(S2="",IF(AI2="",0,AI2),S2)-IF(R2="",0,R2)) | AK2: =IF(C2="","",IF(OR(O2="",P2=""),"Open",IF(ABS(AJ2)<=BEThreshold,"BE",IF(AJ2>0,"Win","Loss")))) | AL2: =IF(OR(C2="",AK2="Open"),"",InitialCapital+SUMIFS($AJ$2:AJ2,$AK$2:AK2,"<>Open")) | AM2: =IF(OR(C2="",AK2=""),"",IF(AK2="Open","No","Yes"))
A3: =IF(C3="","",COUNTA($C$2:C3)) | B3: =IF(C3="","",TEXT(C3,"dddd")) | Y3: =IF($C3="","",IF(E3="XAUUSD",0.1,IF(ISNUMBER(SEARCH("JPY",E3)),0.01,0.0001))) | Z3: =IF($C3="","",IF(F3="Sell",-1,1)) | AA3: =IF($C3="","",IF(E3="XAUUSD",100,100000)) | AB3: =IF(OR(K3="",L3=""),"",ABS(K3-L3)/Y3) | AC3: =IF(OR(K3="",M3=""),"",ABS(M3-K3)/Y3) | AD3: =IF(OR(K3="",O3=""),"",(O3-K3)*Z3/Y3) | AE3: =IF(OR(AB3="",AB3=0,AC3=""),"",AC3/AB3) | AF3: =IF(OR(AB3="",AB3=0,AD3=""),"",AD3/AB3) | AG3: =IF(OR(C3="",P3=""),"",((P3+IF(Q3="",0,Q3))-(C3+IF(D3="",0,D3)))*24) | AH3: =IF(AG3="","",INT(AG3/24)&"d "&INT(MOD(AG3,24))&"h "&INT(MOD(AG3*60,60))&"m") | AI3: =IF(OR(O3="",K3="",H3=""),"",IF(OR(E3="XAUUSD",RIGHT(E3,3)="USD"),(O3-K3)*Z3*AA3*H3,IF(LEFT(E3,3)="USD",IF(O3=0,"",(O3-K3)*Z3*AA3*H3/O3),AD3*10*H3))) | AJ3: =IF(O3="","",IF(S3="",IF(AI3="",0,AI3),S3)-IF(R3="",0,R3)) | AK3: =IF(C3="","",IF(OR(O3="",P3=""),"Open",IF(ABS(AJ3)<=BEThreshold,"BE",IF(AJ3>0,"Win","Loss")))) | AL3: =IF(OR(C3="",AK3="Open"),"",InitialCapital+SUMIFS($AJ$2:AJ3,$AK$2:AK3,"<>Open")) | AM3: =IF(OR(C3="",AK3=""),"",IF(AK3="Open","No","Yes"))
A4: =IF(C4="","",COUNTA($C$2:C4)) | B4: =IF(C4="","",TEXT(C4,"dddd")) | Y4: =IF($C4="","",IF(E4="XAUUSD",0.1,IF(ISNUMBER(SEARCH("JPY",E4)),0.01,0.0001))) | Z4: =IF($C4="","",IF(F4="Sell",-1,1)) | AA4: =IF($C4="","",IF(E4="XAUUSD",100,100000)) | AB4: =IF(OR(K4="",L4=""),"",ABS(K4-L4)/Y4) | AC4: =IF(OR(K4="",M4=""),"",ABS(M4-K4)/Y4) | AD4: =IF(OR(K4="",O4=""),"",(O4-K4)*Z4/Y4) | AE4: =IF(OR(AB4="",AB4=0,AC4=""),"",AC4/AB4) | AF4: =IF(OR(AB4="",AB4=0,AD4=""),"",AD4/AB4) | AG4: =IF(OR(C4="",P4=""),"",((P4+IF(Q4="",0,Q4))-(C4+IF(D4="",0,D4)))*24) | AH4: =IF(AG4="","",INT(AG4/24)&"d "&INT(MOD(AG4,24))&"h "&INT(MOD(AG4*60,60))&"m") | AI4: =IF(OR(O4="",K4="",H4=""),"",IF(OR(E4="XAUUSD",RIGHT(E4,3)="USD"),(O4-K4)*Z4*AA4*H4,IF(LEFT(E4,3)="USD",IF(O4=0,"",(O4-K4)*Z4*AA4*H4/O4),AD4*10*H4))) | AJ4: =IF(O4="","",IF(S4="",IF(AI4="",0,AI4),S4)-IF(R4="",0,R4)) | AK4: =IF(C4="","",IF(OR(O4="",P4=""),"Open",IF(ABS(AJ4)<=BEThreshold,"BE",IF(AJ4>0,"Win","Loss")))) | AL4: =IF(OR(C4="",AK4="Open"),"",InitialCapital+SUMIFS($AJ$2:AJ4,$AK$2:AK4,"<>Open")) | AM4: =IF(OR(C4="",AK4=""),"",IF(AK4="Open","No","Yes"))
A5: =IF(C5="","",COUNTA($C$2:C5)) | B5: =IF(C5="","",TEXT(C5,"dddd")) | Y5: =IF($C5="","",IF(E5="XAUUSD",0.1,IF(ISNUMBER(SEARCH("JPY",E5)),0.01,0.0001))) | Z5: =IF($C5="","",IF(F5="Sell",-1,1)) | AA5: =IF($C5="","",IF(E5="XAUUSD",100,100000)) | AB5: =IF(OR(K5="",L5=""),"",ABS(K5-L5)/Y5) | AC5: =IF(OR(K5="",M5=""),"",ABS(M5-K5)/Y5) | AD5: =IF(OR(K5="",O5=""),"",(O5-K5)*Z5/Y5) | AE5: =IF(OR(AB5="",AB5=0,AC5=""),"",AC5/AB5) | AF5: =IF(OR(AB5="",AB5=0,AD5=""),"",AD5/AB5) | AG5: =IF(OR(C5="",P5=""),"",((P5+IF(Q5="",0,Q5))-(C5+IF(D5="",0,D5)))*24) | AH5: =IF(AG5="","",INT(AG5/24)&"d "&INT(MOD(AG5,24))&"h "&INT(MOD(AG5*60,60))&"m") | AI5: =IF(OR(O5="",K5="",H5=""),"",IF(OR(E5="XAUUSD",RIGHT(E5,3)="USD"),(O5-K5)*Z5*AA5*H5,IF(LEFT(E5,3)="USD",IF(O5=0,"",(O5-K5)*Z5*AA5*H5/O5),AD5*10*H5))) | AJ5: =IF(O5="","",IF(S5="",IF(AI5="",0,AI5),S5)-IF(R5="",0,R5)) | AK5: =IF(C5="","",IF(OR(O5="",P5=""),"Open",IF(ABS(AJ5)<=BEThreshold,"BE",IF(AJ5>0,"Win","Loss")))) | AL5: =IF(OR(C5="",AK5="Open"),"",InitialCapital+SUMIFS($AJ$2:AJ5,$AK$2:AK5,"<>Open")) | AM5: =IF(OR(C5="",AK5=""),"",IF(AK5="Open","No","Yes"))
A6: =IF(C6="","",COUNTA($C$2:C6)) | B6: =IF(C6="","",TEXT(C6,"dddd")) | Y6: =IF($C6="","",IF(E6="XAUUSD",0.1,IF(ISNUMBER(SEARCH("JPY",E6)),0.01,0.0001))) | Z6: =IF($C6="","",IF(F6="Sell",-1,1)) | AA6: =IF($C6="","",IF(E6="XAUUSD",100,100000)) | AB6: =IF(OR(K6="",L6=""),"",ABS(K6-L6)/Y6) | AC6: =IF(OR(K6="",M6=""),"",ABS(M6-K6)/Y6) | AD6: =IF(OR(K6="",O6=""),"",(O6-K6)*Z6/Y6) | AE6: =IF(OR(AB6="",AB6=0,AC6=""),"",AC6/AB6) | AF6: =IF(OR(AB6="",AB6=0,AD6=""),"",AD6/AB6) | AG6: =IF(OR(C6="",P6=""),"",((P6+IF(Q6="",0,Q6))-(C6+IF(D6="",0,D6)))*24) | AH6: =IF(AG6="","",INT(AG6/24)&"d "&INT(MOD(AG6,24))&"h "&INT(MOD(AG6*60,60))&"m") | AI6: =IF(OR(O6="",K6="",H6=""),"",IF(OR(E6="XAUUSD",RIGHT(E6,3)="USD"),(O6-K6)*Z6*AA6*H6,IF(LEFT(E6,3)="USD",IF(O6=0,"",(O6-K6)*Z6*AA6*H6/O6),AD6*10*H6))) | AJ6: =IF(O6="","",IF(S6="",IF(AI6="",0,AI6),S6)-IF(R6="",0,R6)) | AK6: =IF(C6="","",IF(OR(O6="",P6=""),"Open",IF(ABS(AJ6)<=BEThreshold,"BE",IF(AJ6>0,"Win","Loss")))) | AL6: =IF(OR(C6="",AK6="Open"),"",InitialCapital+SUMIFS($AJ$2:AJ6,$AK$2:AK6,"<>Open")) | AM6: =IF(OR(C6="",AK6=""),"",IF(AK6="Open","No","Yes"))
A7: =IF(C7="","",COUNTA($C$2:C7)) | B7: =IF(C7="","",TEXT(C7,"dddd")) | Y7: =IF($C7="","",IF(E7="XAUUSD",0.1,IF(ISNUMBER(SEARCH("JPY",E7)),0.01,0.0001))) | Z7: =IF($C7="","",IF(F7="Sell",-1,1)) | AA7: =IF($C7="","",IF(E7="XAUUSD",100,100000)) | AB7: =IF(OR(K7="",L7=""),"",ABS(K7-L7)/Y7) | AC7: =IF(OR(K7="",M7=""),"",ABS(M7-K7)/Y7) | AD7: =IF(OR(K7="",O7=""),"",(O7-K7)*Z7/Y7) | AE7: =IF(OR(AB7="",AB7=0,AC7=""),"",AC7/AB7) | AF7: =IF(OR(AB7="",AB7=0,AD7=""),"",AD7/AB7) | AG7: =IF(OR(C7="",P7=""),"",((P7+IF(Q7="",0,Q7))-(C7+IF(D7="",0,D7)))*24) | AH7: =IF(AG7="","",INT(AG7/24)&"d "&INT(MOD(AG7,24))&"h "&INT(MOD(AG7*60,60))&"m") | AI7: =IF(OR(O7="",K7="",H7=""),"",IF(OR(E7="XAUUSD",RIGHT(E7,3)="USD"),(O7-K7)*Z7*AA7*H7,IF(LEFT(E7,3)="USD",IF(O7=0,"",(O7-K7)*Z7*AA7*H7/O7),AD7*10*H7))) | AJ7: =IF(O7="","",IF(S7="",IF(AI7="",0,AI7),S7)-IF(R7="",0,R7)) | AK7: =IF(C7="","",IF(OR(O7="",P7=""),"Open",IF(ABS(AJ7)<=BEThreshold,"BE",IF(AJ7>0,"Win","Loss")))) | AL7: =IF(OR(C7="",AK7="Open"),"",InitialCapital+SUMIFS($AJ$2:AJ7,$AK$2:AK7,"<>Open")) | AM7: =IF(OR(C7="",AK7=""),"",IF(AK7="Open","No","Yes"))
A8: =IF(C8="","",COUNTA($C$2:C8)) | B8: =IF(C8="","",TEXT(C8,"dddd")) | Y8: =IF($C8="","",IF(E8="XAUUSD",0.1,IF(ISNUMBER(SEARCH("JPY",E8)),0.01,0.0001))) | Z8: =IF($C8="","",IF(F8="Sell",-1,1)) | AA8: =IF($C8="","",IF(E8="XAUUSD",100,100000)) | AB8: =IF(OR(K8="",L8=""),"",ABS(K8-L8)/Y8) | AC8: =IF(OR(K8="",M8=""),"",ABS(M8-K8)/Y8) | AD8: =IF(OR(K8="",O8=""),"",(O8-K8)*Z8/Y8) | AE8: =IF(OR(AB8="",AB8=0,AC8=""),"",AC8/AB8) | AF8: =IF(OR(AB8="",AB8=0,AD8=""),"",AD8/AB8) | AG8: =IF(OR(C8="",P8=""),"",((P8+IF(Q8="",0,Q8))-(C8+IF(D8="",0,D8)))*24) | AH8: =IF(AG8="","",INT(AG8/24)&"d "&INT(MOD(AG8,24))&"h "&INT(MOD(AG8*60,60))&"m") | AI8: =IF(OR(O8="",K8="",H8=""),"",IF(OR(E8="XAUUSD",RIGHT(E8,3)="USD"),(O8-K8)*Z8*AA8*H8,IF(LEFT(E8,3)="USD",IF(O8=0,"",(O8-K8)*Z8*AA8*H8/O8),AD8*10*H8))) | AJ8: =IF(O8="","",IF(S8="",IF(AI8="",0,AI8),S8)-IF(R8="",0,R8)) | AK8: =IF(C8="","",IF(OR(O8="",P8=""),"Open",IF(ABS(AJ8)<=BEThreshold,"BE",IF(AJ8>0,"Win","Loss")))) | AL8: =IF(OR(C8="",AK8="Open"),"",InitialCapital+SUMIFS($AJ$2:AJ8,$AK$2:AK8,"<>Open")) | AM8: =IF(OR(C8="",AK8=""),"",IF(AK8="Open","No","Yes"))
A9: =IF(C9="","",COUNTA($C$2:C9)) | B9: =IF(C9="","",TEXT(C9,"dddd")) | Y9: =IF($C9="","",IF(E9="XAUUSD",0.1,IF(ISNUMBER(SEARCH("JPY",E9)),0.01,0.0001))) | Z9: =IF($C9="","",IF(F9="Sell",-1,1)) | AA9: =IF($C9="","",IF(E9="XAUUSD",100,100000)) | AB9: =IF(OR(K9="",L9=""),"",ABS(K9-L9)/Y9) | AC9: =IF(OR(K9="",M9=""),"",ABS(M9-K9)/Y9) | AD9: =IF(OR(K9="",O9=""),"",(O9-K9)*Z9/Y9) | AE9: =IF(OR(AB9="",AB9=0,AC9=""),"",AC9/AB9) | AF9: =IF(OR(AB9="",AB9=0,AD9=""),"",AD9/AB9) | AG9: =IF(OR(C9="",P9=""),"",((P9+IF(Q9="",0,Q9))-(C9+IF(D9="",0,D9)))*24) | AH9: =IF(AG9="","",INT(AG9/24)&"d "&INT(MOD(AG9,24))&"h "&INT(MOD(AG9*60,60))&"m") | AI9: =IF(OR(O9="",K9="",H9=""),"",IF(OR(E9="XAUUSD",RIGHT(E9,3)="USD"),(O9-K9)*Z9*AA9*H9,IF(LEFT(E9,3)="USD",IF(O9=0,"",(O9-K9)*Z9*AA9*H9/O9),AD9*10*H9))) | AJ9: =IF(O9="","",IF(S9="",IF(AI9="",0,AI9),S9)-IF(R9="",0,R9)) | AK9: =IF(C9="","",IF(OR(O9="",P9=""),"Open",IF(ABS(AJ9)<=BEThreshold,"BE",IF(AJ9>0,"Win","Loss")))) | AL9: =IF(OR(C9="",AK9="Open"),"",InitialCapital+SUMIFS($AJ$2:AJ9,$AK$2:AK9,"<>Open")) | AM9: =IF(OR(C9="",AK9=""),"",IF(AK9="Open","No","Yes"))
A10: =IF(C10="","",COUNTA($C$2:C10)) | B10: =IF(C10="","",TEXT(C10,"dddd")) | Y10: =IF($C10="","",IF(E10="XAUUSD",0.1,IF(ISNUMBER(SEARCH("JPY",E10)),0.01,0.0001))) | Z10: =IF($C10="","",IF(F10="Sell",-1,1)) | AA10: =IF($C10="","",IF(E10="XAUUSD",100,100000)) | AB10: =IF(OR(K10="",L10=""),"",ABS(K10-L10)/Y10) | AC10: =IF(OR(K10="",M10=""),"",ABS(M10-K10)/Y10) | AD10: =IF(OR(K10="",O10=""),"",(O10-K10)*Z10/Y10) | AE10: =IF(OR(AB10="",AB10=0,AC10=""),"",AC10/AB10) | AF10: =IF(OR(AB10="",AB10=0,AD10=""),"",AD10/AB10) | AG10: =IF(OR(C10="",P10=""),"",((P10+IF(Q10="",0,Q10))-(C10+IF(D10="",0,D10)))*24) | AH10: =IF(AG10="","",INT(AG10/24)&"d "&INT(MOD(AG10,24))&"h "&INT(MOD(AG10*60,60))&"m") | AI10: =IF(OR(O10="",K10="",H10=""),"",IF(OR(E10="XAUUSD",RIGHT(E10,3)="USD"),(O10-K10)*Z10*AA10*H10,IF(LEFT(E10,3)="USD",IF(O10=0,"",(O10-K10)*Z10*AA10*H10/O10),AD10*10*H10))) | AJ10: =IF(O10="","",IF(S10="",IF(AI10="",0,AI10),S10)-IF(R10="",0,R10)) | AK10: =IF(C10="","",IF(OR(O10="",P10=""),"Open",IF(ABS(AJ10)<=BEThreshold,"BE",IF(AJ10>0,"Win","Loss")))) | AL10: =IF(OR(C10="",AK10="Open"),"",InitialCapital+SUMIFS($AJ$2:AJ10,$AK$2:AK10,"<>Open")) | AM10: =IF(OR(C10="",AK10=""),"",IF(AK10="Open","No","Yes"))
A11: =IF(C11="","",COUNTA($C$2:C11)) | B11: =IF(C11="","",TEXT(C11,"dddd")) | Y11: =IF($C11="","",IF(E11="XAUUSD",0.1,IF(ISNUMBER(SEARCH("JPY",E11)),0.01,0.0001))) | Z11: =IF($C11="","",IF(F11="Sell",-1,1)) | AA11: =IF($C11="","",IF(E11="XAUUSD",100,100000)) | AB11: =IF(OR(K11="",L11=""),"",ABS(K11-L11)/Y11) | AC11: =IF(OR(K11="",M11=""),"",ABS(M11-K11)/Y11) | AD11: =IF(OR(K11="",O11=""),"",(O11-K11)*Z11/Y11) | AE11: =IF(OR(AB11="",AB11=0,AC11=""),"",AC11/AB11) | AF11: =IF(OR(AB11="",AB11=0,AD11=""),"",AD11/AB11) | AG11: =IF(OR(C11="",P11=""),"",((P11+IF(Q11="",0,Q11))-(C11+IF(D11="",0,D11)))*24) | AH11: =IF(AG11="","",INT(AG11/24)&"d "&INT(MOD(AG11,24))&"h "&INT(MOD(AG11*60,60))&"m") | AI11: =IF(OR(O11="",K11="",H11=""),"",IF(OR(E11="XAUUSD",RIGHT(E11,3)="USD"),(O11-K11)*Z11*AA11*H11,IF(LEFT(E11,3)="USD",IF(O11=0,"",(O11-K11)*Z11*AA11*H11/O11),AD11*10*H11))) | AJ11: =IF(O11="","",IF(S11="",IF(AI11="",0,AI11),S11)-IF(R11="",0,R11)) | AK11: =IF(C11="","",IF(OR(O11="",P11=""),"Open",IF(ABS(AJ11)<=BEThreshold,"BE",IF(AJ11>0,"Win","Loss")))) | AL11: =IF(OR(C11="",AK11="Open"),"",InitialCapital+SUMIFS($AJ$2:AJ11,$AK$2:AK11,"<>Open")) | AM11: =IF(OR(C11="",AK11=""),"",IF(AK11="Open","No","Yes"))
A12: =IF(C12="","",COUNTA($C$2:C12)) | B12: =IF(C12="","",TEXT(C12,"dddd")) | Y12: =IF($C12="","",IF(E12="XAUUSD",0.1,IF(ISNUMBER(SEARCH("JPY",E12)),0.01,0.0001))) | Z12: =IF($C12="","",IF(F12="Sell",-1,1)) | AA12: =IF($C12="","",IF(E12="XAUUSD",100,100000)) | AB12: =IF(OR(K12="",L12=""),"",ABS(K12-L12)/Y12) | AC12: =IF(OR(K12="",M12=""),"",ABS(M12-K12)/Y12) | AD12: =IF(OR(K12="",O12=""),"",(O12-K12)*Z12/Y12) | AE12: =IF(OR(AB12="",AB12=0,AC12=""),"",AC12/AB12) | AF12: =IF(OR(AB12="",AB12=0,AD12=""),"",AD12/AB12) | AG12: =IF(OR(C12="",P12=""),"",((P12+IF(Q12="",0,Q12))-(C12+IF(D12="",0,D12)))*24) | AH12: =IF(AG12="","",INT(AG12/24)&"d "&INT(MOD(AG12,24))&"h "&INT(MOD(AG12*60,60))&"m") | AI12: =IF(OR(O12="",K12="",H12=""),"",IF(OR(E12="XAUUSD",RIGHT(E12,3)="USD"),(O12-K12)*Z12*AA12*H12,IF(LEFT(E12,3)="USD",IF(O12=0,"",(O12-K12)*Z12*AA12*H12/O12),AD12*10*H12))) | AJ12: =IF(O12="","",IF(S12="",IF(AI12="",0,AI12),S12)-IF(R12="",0,R12)) | AK12: =IF(C12="","",IF(OR(O12="",P12=""),"Open",IF(ABS(AJ12)<=BEThreshold,"BE",IF(AJ12>0,"Win","Loss")))) | AL12: =IF(OR(C12="",AK12="Open"),"",InitialCapital+SUMIFS($AJ$2:AJ12,$AK$2:AK12,"<>Open")) | AM12: =IF(OR(C12="",AK12=""),"",IF(AK12="Open","No","Yes"))
A13: =IF(C13="","",COUNTA($C$2:C13)) | B13: =IF(C13="","",TEXT(C13,"dddd")) | Y13: =IF($C13="","",IF(E13="XAUUSD",0.1,IF(ISNUMBER(SEARCH("JPY",E13)),0.01,0.0001))) | Z13: =IF($C13="","",IF(F13="Sell",-1,1)) | AA13: =IF($C13="","",IF(E13="XAUUSD",100,100000)) | AB13: =IF(OR(K13="",L13=""),"",ABS(K13-L13)/Y13) | AC13: =IF(OR(K13="",M13=""),"",ABS(M13-K13)/Y13) | AD13: =IF(OR(K13="",O13=""),"",(O13-K13)*Z13/Y13) | AE13: =IF(OR(AB13="",AB13=0,AC13=""),"",AC13/AB13) | AF13: =IF(OR(AB13="",AB13=0,AD13=""),"",AD13/AB13) | AG13: =IF(OR(C13="",P13=""),"",((P13+IF(Q13="",0,Q13))-(C13+IF(D13="",0,D13)))*24) | AH13: =IF(AG13="","",INT(AG13/24)&"d "&INT(MOD(AG13,24))&"h "&INT(MOD(AG13*60,60))&"m") | AI13: =IF(OR(O13="",K13="",H13=""),"",IF(OR(E13="XAUUSD",RIGHT(E13,3)="USD"),(O13-K13)*Z13*AA13*H13,IF(LEFT(E13,3)="USD",IF(O13=0,"",(O13-K13)*Z13*AA13*H13/O13),AD13*10*H13))) | AJ13: =IF(O13="","",IF(S13="",IF(AI13="",0,AI13),S13)-IF(R13="",0,R13)) | AK13: =IF(C13="","",IF(OR(O13="",P13=""),"Open",IF(ABS(AJ13)<=BEThreshold,"BE",IF(AJ13>0,"Win","Loss")))) | AL13: =IF(OR(C13="",AK13="Open"),"",InitialCapital+SUMIFS($AJ$2:AJ13,$AK$2:AK13,"<>Open")) | AM13: =IF(OR(C13="",AK13=""),"",IF(AK13="Open","No","Yes"))
... A401: =IF(C401="","",COUNTA($C$2:C401)) | B401: =IF(C401="","",TEXT(C401,"dddd")) | Y401: =IF($C401="","",IF(E401="XAUUSD",0.1,IF(ISNUMBER(SEARCH("JPY",E401)),0.01,0.0001))) | Z401: =IF($C401="","",IF(F401="Sell",-1,1)) | AA401: =IF($C401="","",IF(E401="XAUUSD",100,100000)) | AB401: =IF(OR(K401="",L401=""),"",ABS(K401-L401)/Y401) | AC401: =IF(OR(K401="",M401=""),"",ABS(M401-K401)/Y401) | AD401: =IF(OR(K401="",O401=""),"",(O401-K401)*Z401/Y401) | AE401: =IF(OR(AB401="",AB401=0,AC401=""),"",AC401/AB401) | AF401: =IF(OR(AB401="",AB401=0,AD401=""),"",AD401/AB401) | AG401: =IF(OR(C401="",P401=""),"",((P401+IF(Q401="",0,Q401))-(C401+IF(D401="",0,D401)))*24) | AH401: =IF(AG401="","",INT(AG401/24)&"d "&INT(MOD(AG401,24))&"h "&INT(MOD(AG401*60,60))&"m") | AI401: =IF(OR(O401="",K401="",H401=""),"",IF(OR(E401="XAUUSD",RIGHT(E401,3)="USD"),(O401-K401)*Z401*AA401*H401,IF(LEFT(E401,3)="USD",IF(O401=0,"",(O401-K401)*Z401*AA401*H401/O401),AD401*10*H401))) | AJ401: =IF(O401="","",IF(S401="",IF(AI401="",0,AI401),S401)-IF(R401="",0,R401)) | AK401: =IF(C401="","",IF(OR(O401="",P401=""),"Open",IF(ABS(AJ401)<=BEThreshold,"BE",IF(AJ401>0,"Win","Loss")))) | AL401: =IF(OR(C401="",AK401="Open"),"",InitialCapital+SUMIFS($AJ$2:AJ401,$AK$2:AK401,"<>Open")) | AM401: =IF(OR(C401="",AK401=""),"",IF(AK401="Open","No","Yes"))

Sheet 03_Dashboard
A1: AURUM LEDGER · PERFORMANCE DESK
A2: Filters drive every KPI, chart and table on this sheet. Open trades are excluded.
A4: FILTERS
A5: PAIR | C5: WEEKDAY | E5: SESSION | G5: SETUP | I5: FROM | K5: TO | N5: Reset filters → set each dropdown to All and clear dates.
B6: All | D6: All | F6: All | H6: All
A8: HEADLINE KPIs (filtered closed trades only)
A10: CLOSED TRADES | C10: WIN RATE | E10: TOTAL PnL | G10: PROFIT FACTOR | I10: EQUITY | K10: EXPECTANCY
A11: =B20 | C11: =B31 | E11: =B24 | G11: =B32 | I11: =B33 | K11: =B34
A13: WINS | C13: LOSSES | E13: BREAKEVEN | G13: LARGEST WIN* | I13: LARGEST LOSS* | K13: AVG WIN / AVG LOSS
A14: =B21 | C14: =B22 | E14: =B23 | G14: =B27 | I14: =B28 | K14: =IF(OR(B29="—",B30="—"),"—",TEXT(B29,"#,##0.00")&" / "&TEXT(B30,"#,##0.00"))
A16: Largest win/loss marked * use the unfiltered log (Excel limitation). The web desk applies filters to those two figures. All other KPIs honour the dropdowns.
A17: =IF(B20=0,"No closed trades in this slice. Enter tickets on 02_Trade_Log.","Slice · "&B20&" closed · "&TEXT(B21,"0")&"W "&TEXT(B22,"0")&"L "&TEXT(B23,"0")&" BE · PnL "&TEXT(B24,"+#,##0.00;-#,##0.00"))
A19: ENGINE (do not edit)
A20: Closed | B20: =SUMPRODUCT((('02_Trade_Log'!$AK$2:$AK$401<>"Open")*('02_Trade_Log'!$C$2:$C$401<>"")*(('03_Dashboard'!$B$6="All")+('02_Trade_Log'!$E$2:$E$401='03_Dashboard'!$B$6))*(('03_Dashboard'!$D$6="All")+('02_Trade_Log'!$B$2:$B$401='03_Dashboard'!$D$6))*(('03_Dashboard'!$F$6="All")+('02_Trade_Log'!$G$2:$G$401='03_Dashboard'!$F$6))*(('03_Dashboard'!$H$6="All")+('02_Trade_Log'!$N$2:$N$401='03_Dashboard'!$H$6))*(('03_Dashboard'!$J$6="")+('02_Trade_Log'!$C$2:$C$401>='03_Dashboard'!$J$6))*(('03_Dashboard'!$L$6="")+('02_Trade_Log'!$C$2:$C$401<='03_Dashboard'!$L$6))))
A21: Wins | B21: =SUMPRODUCT((('02_Trade_Log'!$AK$2:$AK$401<>"Open")*('02_Trade_Log'!$C$2:$C$401<>"")*(('03_Dashboard'!$B$6="All")+('02_Trade_Log'!$E$2:$E$401='03_Dashboard'!$B$6))*(('03_Dashboard'!$D$6="All")+('02_Trade_Log'!$B$2:$B$401='03_Dashboard'!$D$6))*(('03_Dashboard'!$F$6="All")+('02_Trade_Log'!$G$2:$G$401='03_Dashboard'!$F$6))*(('03_Dashboard'!$H$6="All")+('02_Trade_Log'!$N$2:$N$401='03_Dashboard'!$H$6))*(('03_Dashboard'!$J$6="")+('02_Trade_Log'!$C$2:$C$401>='03_Dashboard'!$J$6))*(('03_Dashboard'!$L$6="")+('02_Trade_Log'!$C$2:$C$401<='03_Dashboard'!$L$6)))*('02_Trade_Log'!$AK$2:$AK$401="Win"))
A22: Losses | B22: =SUMPRODUCT((('02_Trade_Log'!$AK$2:$AK$401<>"Open")*('02_Trade_Log'!$C$2:$C$401<>"")*(('03_Dashboard'!$B$6="All")+('02_Trade_Log'!$E$2:$E$401='03_Dashboard'!$B$6))*(('03_Dashboard'!$D$6="All")+('02_Trade_Log'!$B$2:$B$401='03_Dashboard'!$D$6))*(('03_Dashboard'!$F$6="All")+('02_Trade_Log'!$G$2:$G$401='03_Dashboard'!$F$6))*(('03_Dashboard'!$H$6="All")+('02_Trade_Log'!$N$2:$N$401='03_Dashboard'!$H$6))*(('03_Dashboard'!$J$6="")+('02_Trade_Log'!$C$2:$C$401>='03_Dashboard'!$J$6))*(('03_Dashboard'!$L$6="")+('02_Trade_Log'!$C$2:$C$401<='03_Dashboard'!$L$6)))*('02_Trade_Log'!$AK$2:$AK$401="Loss"))
A23: BE | B23: =SUMPRODUCT((('02_Trade_Log'!$AK$2:$AK$401<>"Open")*('02_Trade_Log'!$C$2:$C$401<>"")*(('03_Dashboard'!$B$6="All")+('02_Trade_Log'!$E$2:$E$401='03_Dashboard'!$B$6))*(('03_Dashboard'!$D$6="All")+('02_Trade_Log'!$B$2:$B$401='03_Dashboard'!$D$6))*(('03_Dashboard'!$F$6="All")+('02_Trade_Log'!$G$2:$G$401='03_Dashboard'!$F$6))*(('03_Dashboard'!$H$6="All")+('02_Trade_Log'!$N$2:$N$401='03_Dashboard'!$H$6))*(('03_Dashboard'!$J$6="")+('02_Trade_Log'!$C$2:$C$401>='03_Dashboard'!$J$6))*(('03_Dashboard'!$L$6="")+('02_Trade_Log'!$C$2:$C$401<='03_Dashboard'!$L$6)))*('02_Trade_Log'!$AK$2:$AK$401="BE"))
A24: Total PnL | B24: =SUMPRODUCT((('02_Trade_Log'!$AK$2:$AK$401<>"Open")*('02_Trade_Log'!$C$2:$C$401<>"")*(('03_Dashboard'!$B$6="All")+('02_Trade_Log'!$E$2:$E$401='03_Dashboard'!$B$6))*(('03_Dashboard'!$D$6="All")+('02_Trade_Log'!$B$2:$B$401='03_Dashboard'!$D$6))*(('03_Dashboard'!$F$6="All")+('02_Trade_Log'!$G$2:$G$401='03_Dashboard'!$F$6))*(('03_Dashboard'!$H$6="All")+('02_Trade_Log'!$N$2:$N$401='03_Dashboard'!$H$6))*(('03_Dashboard'!$J$6="")+('02_Trade_Log'!$C$2:$C$401>='03_Dashboard'!$J$6))*(('03_Dashboard'!$L$6="")+('02_Trade_Log'!$C$2:$C$401<='03_Dashboard'!$L$6)))*('02_Trade_Log'!$AJ$2:$AJ$401))
A25: Gross profit | B25: =SUMPRODUCT((('02_Trade_Log'!$AK$2:$AK$401<>"Open")*('02_Trade_Log'!$C$2:$C$401<>"")*(('03_Dashboard'!$B$6="All")+('02_Trade_Log'!$E$2:$E$401='03_Dashboard'!$B$6))*(('03_Dashboard'!$D$6="All")+('02_Trade_Log'!$B$2:$B$401='03_Dashboard'!$D$6))*(('03_Dashboard'!$F$6="All")+('02_Trade_Log'!$G$2:$G$401='03_Dashboard'!$F$6))*(('03_Dashboard'!$H$6="All")+('02_Trade_Log'!$N$2:$N$401='03_Dashboard'!$H$6))*(('03_Dashboard'!$J$6="")+('02_Trade_Log'!$C$2:$C$401>='03_Dashboard'!$J$6))*(('03_Dashboard'!$L$6="")+('02_Trade_Log'!$C$2:$C$401<='03_Dashboard'!$L$6)))*('02_Trade_Log'!$AJ$2:$AJ$401>0)*('02_Trade_Log'!$AJ$2:$AJ$401))
A26: Gross loss signed | B26: =SUMPRODUCT((('02_Trade_Log'!$AK$2:$AK$401<>"Open")*('02_Trade_Log'!$C$2:$C$401<>"")*(('03_Dashboard'!$B$6="All")+('02_Trade_Log'!$E$2:$E$401='03_Dashboard'!$B$6))*(('03_Dashboard'!$D$6="All")+('02_Trade_Log'!$B$2:$B$401='03_Dashboard'!$D$6))*(('03_Dashboard'!$F$6="All")+('02_Trade_Log'!$G$2:$G$401='03_Dashboard'!$F$6))*(('03_Dashboard'!$H$6="All")+('02_Trade_Log'!$N$2:$N$401='03_Dashboard'!$H$6))*(('03_Dashboard'!$J$6="")+('02_Trade_Log'!$C$2:$C$401>='03_Dashboard'!$J$6))*(('03_Dashboard'!$L$6="")+('02_Trade_Log'!$C$2:$C$401<='03_Dashboard'!$L$6)))*('02_Trade_Log'!$AJ$2:$AJ$401<0)*('02_Trade_Log'!$AJ$2:$AJ$401))
A27: Largest win* | B27: =IF(B21=0,"—",MAXIFS('02_Trade_Log'!$AJ$2:$AJ$401,'02_Trade_Log'!$AK$2:$AK$401,"Win",'02_Trade_Log'!$C$2:$C$401,"<>"))
A28: Largest loss* | B28: =IF(B22=0,"—",MINIFS('02_Trade_Log'!$AJ$2:$AJ$401,'02_Trade_Log'!$AK$2:$AK$401,"Loss",'02_Trade_Log'!$C$2:$C$401,"<>"))
A29: Avg win | B29: =IF(B21=0,"—",B25/B21)
A30: Avg loss | B30: =IF(B22=0,"—",B26/B22)
A31: Win rate | B31: =IF(B20=0,"—",B21/B20)
A32: Profit factor | B32: =IF(ABS(B26)=0,IF(B25>0,"∞","—"),B25/ABS(B26))
A33: Equity | B33: =InitialCapital+B24
A34: Expectancy | B34: =IF(B20=0,"—",B24/B20)
A35: Win rate excl BE | B35: =IF(B21+B22=0,"—",B21/(B21+B22))
A47: Charts read 04_Breakdowns (live). Equity uses the first 80 log rows — keep trades at the top of 02_Trade_Log.

Sheet 04_Breakdowns
A1: AURUM LEDGER · BREAKDOWNS
A2: Pair, weekday, session, setup, monthly. Same filters as the dashboard.
A4: BY CURRENCY PAIR | N4: CHART DATA (dashboard)
A5: Slice | B5: Trades | C5: Wins | D5: Losses | E5: BE | F5: Win rate | G5: PnL | H5: Profit factor | I5: Avg win | J5: Avg loss | K5: Avg trade | N5: Weekday | O5: PnL | P5: Win rate
A6: AUDCHF | B6: =SUMPRODUCT((('02_Trade_Log'!$AK$2:$AK$401<>"Open")*('02_Trade_Log'!$C$2:$C$401<>"")*(('03_Dashboard'!$D$6="All")+('02_Trade_Log'!$B$2:$B$401='03_Dashboard'!$D$6))*(('03_Dashboard'!$F$6="All")+('02_Trade_Log'!$G$2:$G$401='03_Dashboard'!$F$6))*(('03_Dashboard'!$H$6="All")+('02_Trade_Log'!$N$2:$N$401='03_Dashboard'!$H$6))*(('03_Dashboard'!$J$6="")+('02_Trade_Log'!$C$2:$C$401>='03_Dashboard'!$J$6))*(('03_Dashboard'!$L$6="")+('02_Trade_Log'!$C$2:$C$401<='03_Dashboard'!$L$6)))*(('02_Trade_Log'!$E$2:$E$401=A6))) | C6: =SUMPRODUCT((('02_Trade_Log'!$AK$2:$AK$401<>"Open")*('02_Trade_Log'!$C$2:$C$401<>"")*(('03_Dashboard'!$D$6="All")+('02_Trade_Log'!$B$2:$B$401='03_Dashboard'!$D$6))*(('03_Dashboard'!$F$6="All")+('02_Trade_Log'!$G$2:$G$401='03_Dashboard'!$F$6))*(('03_Dashboard'!$H$6="All")+('02_Trade_Log'!$N$2:$N$401='03_Dashboard'!$H$6))*(('03_Dashboard'!$J$6="")+('02_Trade_Log'!$C$2:$C$401>='03_Dashboard'!$J$6))*(('03_Dashboard'!$L$6="")+('02_Trade_Log'!$C$2:$C$401<='03_Dashboard'!$L$6)))*(('02_Trade_Log'!$E$2:$E$401=A6))*('02_Trade_Log'!$AK$2:$AK$401="Win")) | D6: =SUMPRODUCT((('02_Trade_Log'!$AK$2:$AK$401<>"Open")*('02_Trade_Log'!$C$2:$C$401<>"")*(('03_Dashboard'!$D$6="All")+('02_Trade_Log'!$B$2:$B$401='03_Dashboard'!$D$6))*(('03_Dashboard'!$F$6="All")+('02_Trade_Log'!$G$2:$G$401='03_Dashboard'!$F$6))*(('03_Dashboard'!$H$6="All")+('02_Trade_Log'!$N$2:$N$401='03_Dashboard'!$H$6))*(('03_Dashboard'!$J$6="")+('02_Trade_Log'!$C$2:$C$401>='03_Dashboard'!$J$6))*(('03_Dashboard'!$L$6="")+('02_Trade_Log'!$C$2:$C$401<='03_Dashboard'!$L$6)))*(('02_Trade_Log'!$E$2:$E$401=A6))*('02_Trade_Log'!$AK$2:$AK$401="Loss")) | E6: =SUMPRODUCT((('02_Trade_Log'!$AK$2:$AK$401<>"Open")*('02_Trade_Log'!$C$2:$C$401<>"")*(('03_Dashboard'!$D$6="All")+('02_Trade_Log'!$B$2:$B$401='03_Dashboard'!$D$6))*(('03_Dashboard'!$F$6="All")+('02_Trade_Log'!$G$2:$G$401='03_Dashboard'!$F$6))*(('03_Dashboard'!$H$6="All")+('02_Trade_Log'!$N$2:$N$401='03_Dashboard'!$H$6))*(('03_Dashboard'!$J$6="")+('02_Trade_Log'!$C$2:$C$401>='03_Dashboard'!$J$6))*(('03_Dashboard'!$L$6="")+('02_Trade_Log'!$C$2:$C$401<='03_Dashboard'!$L$6)))*(('02_Trade_Log'!$E$2:$E$401=A6))*('02_Trade_Log'!$AK$2:$AK$401="BE")) | F6: =IF(B6=0,"—",C6/B6) | G6: =SUMPRODUCT((('02_Trade_Log'!$AK$2:$AK$401<>"Open")*('02_Trade_Log'!$C$2:$C$401<>"")*(('03_Dashboard'!$D$6="All")+('02_Trade_Log'!$B$2:$B$401='03_Dashboard'!$D$6))*(('03_Dashboard'!$F$6="All")+('02_Trade_Log'!$G$2:$G$401='03_Dashboard'!$F$6))*(('03_Dashboard'!$H$6="All")+('02_Trade_Log'!$N$2:$N$401='03_Dashboard'!$H$6))*(('03_Dashboard'!$J$6="")+('02_Trade_Log'!$C$2:$C$401>='03_Dashboard'!$J$6))*(('03_Dashboard'!$L$6="")+('02_Trade_Log'!$C$2:$C$401<='03_Dashboard'!$L$6)))*(('02_Trade_Log'!$E$2:$E$401=A6))*('02_Trade_Log'!$AJ$2:$AJ$401)) | H6: =IF(SUMPRODUCT((('02_Trade_Log'!$AK$2:$AK$401<>"Open")*('02_Trade_Log'!$C$2:$C$401<>"")*(('03_Dashboard'!$D$6="All")+('02_Trade_Log'!$B$2:$B$401='03_Dashboard'!$D$6))*(('03_Dashboard'!$F$6="All")+('02_Trade_Log'!$G$2:$G$401='03_Dashboard'!$F$6))*(('03_Dashboard'!$H$6="All")+('02_Trade_Log'!$N$2:$N$401='03_Dashboard'!$H$6))*(('03_Dashboard'!$J$6="")+('02_Trade_Log'!$C$2:$C$401>='03_Dashboard'!$J$6))*(('03_Dashboard'!$L$6="")+('02_Trade_Log'!$C$2:$C$401<='03_Dashboard'!$L$6)))*(('02_Trade_Log'!$E$2:$E$401=A6))*('02_Trade_Log'!$AJ$2:$AJ$401<0)*('02_Trade_Log'!$AJ$2:$AJ$401))=0,IF(SUMPRODUCT((('02_Trade_Log'!$AK$2:$AK$401<>"Open")*('02_Trade_Log'!$C$2:$C$401<>"")*(('03_Dashboard'!$D$6="All")+('02_Trade_Log'!$B$2:$B$401='03_Dashboard'!$D$6))*(('03_Dashboard'!$F$6="All")+('02_Trade_Log'!$G$2:$G$401='03_Dashboard'!$F$6))*(('03_Dashboard'!$H$6="All")+('02_Trade_Log'!$N$2:$N$401='03_Dashboard'!$H$6))*(('03_Dashboard'!$J$6="")+('02_Trade_Log'!$C$2:$C$401>='03_Dashboard'!$J$6))*(('03_Dashboard'!$L$6="")+('02_Trade_Log'!$C$2:$C$401<='03_Dashboard'!$L$6)))*(('02_Trade_Log'!$E$2:$E$401=A6))*('02_Trade_Log'!$AJ$2:$AJ$401>0)*('02_Trade_Log'!$AJ$2:$AJ$401))>0,"∞","—"),SUMPRODUCT((('02_Trade_Log'!$AK$2:$AK$401<>"Open")*('02_Trade_Log'!$C$2:$C$401<>"")*(('03_Dashboard'!$D$6="All")+('02_Trade_Log'!$B$2:$B$401='03_Dashboard'!$D$6))*(('03_Dashboard'!$F$6="All")+('02_Trade_Log'!$G$2:$G$401='03_Dashboard'!$F$6))*(('03_Dashboard'!$H$6="All")+('02_Trade_Log'!$N$2:$N$401='03_Dashboard'!$H$6))*(('03_Dashboard'!$J$6="")+('02_Trade_Log'!$C$2:$C$401>='03_Dashboard'!$J$6))*(('03_Dashboard'!$L$6="")+('02_Trade_Log'!$C$2:$C$401<='03_Dashboard'!$L$6)))*(('02_Trade_Log'!$E$2:$E$401=A6))*('02_Trade_Log'!$AJ$2:$AJ$401>0)*('02_Trade_Log'!$AJ$2:$AJ$401))/ABS(SUMPRODUCT((('02_Trade_Log'!$AK$2:$AK$401<>"Open")*('02_Trade_Log'!$C$2:$C$401<>"")*(('03_Dashboard'!$D$6="All")+('02_Trade_Log'!$B$2:$B$401='03_Dashboard'!$D$6))*(('03_Dashboard'!$F$6="All")+('02_Trade_Log'!$G$2:$G$401='03_Dashboard'!$F$6))*(('03_Dashboard'!$H$6="All")+('02_Trade_Log'!$N$2:$N$401='03_Dashboard'!$H$6))*(('03_Dashboard'!$J$6="")+('02_Trade_Log'!$C$2:$C$401>='03_Dashboard'!$J$6))*(('03_Dashboard'!$L$6="")+('02_Trade_Log'!$C$2:$C$401<='03_Dashboard'!$L$6)))*(('02_Trade_Log'!$E$2:$E$401=A6))*('02_Trade_Log'!$AJ$2:$AJ$401<0)*('02_Trade_Log'!$AJ$2:$AJ$401)))) | I6: =IF(C6=0,"—",SUMPRODUCT((('02_Trade_Log'!$AK$2:$AK$401<>"Open")*('02_Trade_Log'!$C$2:$C$401<>"")*(('03_Dashboard'!$D$6="All")+('02_Trade_Log'!$B$2:$B$401='03_Dashboard'!$D$6))*(('03_Dashboard'!$F$6="All")+('02_Trade_Log'!$G$2:$G$401='03_Dashboard'!$F$6))*(('03_Dashboard'!$H$6="All")+('02_Trade_Log'!$N$2:$N$401='03_Dashboard'!$H$6))*(('03_Dashboard'!$J$6="")+('02_Trade_Log'!$C$2:$C$401>='03_Dashboard'!$J$6))*(('03_Dashboard'!$L$6="")+('02_Trade_Log'!$C$2:$C$401<='03_Dashboard'!$L$6)))*(('02_Trade_Log'!$E$2:$E$401=A6))*('02_Trade_Log'!$AK$2:$AK$401="Win")*('02_Trade_Log'!$AJ$2:$AJ$401))/C6) | J6: =IF(D6=0,"—",SUMPRODUCT((('02_Trade_Log'!$AK$2:$AK$401<>"Open")*('02_Trade_Log'!$C$2:$C$401<>"")*(('03_Dashboard'!$D$6="All")+('02_Trade_Log'!$B$2:$B$401='03_Dashboard'!$D$6))*(('03_Dashboard'!$F$6="All")+('02_Trade_Log'!$G$2:$G$401='03_Dashboard'!$F$6))*(('03_Dashboard'!$H$6="All")+('02_Trade_Log'!$N$2:$N$401='03_Dashboard'!$H$6))*(('03_Dashboard'!$J$6="")+('02_Trade_Log'!$C$2:$C$401>='03_Dashboard'!$J$6))*(('03_Dashboard'!$L$6="")+('02_Trade_Log'!$C$2:$C$401<='03_Dashboard'!$L$6)))*(('02_Trade_Log'!$E$2:$E$401=A6))*('02_Trade_Log'!$AK$2:$AK$401="Loss")*('02_Trade_Log'!$AJ$2:$AJ$401))/D6) | K6: =IF(B6=0,"—",G6/B6) | N6: =A39 | O6: =G39 | P6: =IF(ISNUMBER(F39),F39,0)
A7: AUDJPY | B7: =SUMPRODUCT((('02_Trade_Log'!$AK$2:$AK$401<>"Open")*('02_Trade_Log'!$C$2:$C$401<>"")*(('03_Dashboard'!$D$6="All")+('02_Trade_Log'!$B$2:$B$401='03_Dashboard'!$D$6))*(('03_Dashboard'!$F$6="All")+('02_Trade_Log'!$G$2:$G$401='03_Dashboard'!$F$6))*(('03_Dashboard'!$H$6="All")+('02_Trade_Log'!$N$2:$N$401='03_Dashboard'!$H$6))*(('03_Dashboard'!$J$6="")+('02_Trade_Log'!$C$2:$C$401>='03_Dashboard'!$J$6))*(('03_Dashboard'!$L$6="")+('02_Trade_Log'!$C$2:$C$401<='03_Dashboard'!$L$6)))*(('02_Trade_Log'!$E$2:$E$401=A7))) | C7: =SUMPRODUCT((('02_Trade_Log'!$AK$2:$AK$401<>"Open")*('02_Trade_Log'!$C$2:$C$401<>"")*(('03_Dashboard'!$D$6="All")+('02_Trade_Log'!$B$2:$B$401='03_Dashboard'!$D$6))*(('03_Dashboard'!$F$6="All")+('02_Trade_Log'!$G$2:$G$401='03_Dashboard'!$F$6))*(('03_Dashboard'!$H$6="All")+('02_Trade_Log'!$N$2:$N$401='03_Dashboard'!$H$6))*(('03_Dashboard'!$J$6="")+('02_Trade_Log'!$C$2:$C$401>='03_Dashboard'!$J$6))*(('03_Dashboard'!$L$6="")+('02_Trade_Log'!$C$2:$C$401<='03_Dashboard'!$L$6)))*(('02_Trade_Log'!$E$2:$E$401=A7))*('02_Trade_Log'!$AK$2:$AK$401="Win")) | D7: =SUMPRODUCT((('02_Trade_Log'!$AK$2:$AK$401<>"Open")*('02_Trade_Log'!$C$2:$C$401<>"")*(('03_Dashboard'!$D$6="All")+('02_Trade_Log'!$B$2:$B$401='03_Dashboard'!$D$6))*(('03_Dashboard'!$F$6="All")+('02_Trade_Log'!$G$2:$G$401='03_Dashboard'!$F$6))*(('03_Dashboard'!$H$6="All")+('02_Trade_Log'!$N$2:$N$401='03_Dashboard'!$H$6))*(('03_Dashboard'!$J$6="")+('02_Trade_Log'!$C$2:$C$401>='03_Dashboard'!$J$6))*(('03_Dashboard'!$L$6="")+('02_Trade_Log'!$C$2:$C$401<='03_Dashboard'!$L$6)))*(('02_Trade_Log'!$E$2:$E$401=A7))*('02_Trade_Log'!$AK$2:$AK$401="Loss")) | E7: =SUMPRODUCT((('02_Trade_Log'!$AK$2:$AK$401<>"Open")*('02_Trade_Log'!$C$2:$C$401<>"")*(('03_Dashboard'!$D$6="All")+('02_Trade_Log'!$B$2:$B$401='03_Dashboard'!$D$6))*(('03_Dashboard'!$F$6="All")+('02_Trade_Log'!$G$2:$G$401='03_Dashboard'!$F$6))*(('03_Dashboard'!$H$6="All")+('02_Trade_Log'!$N$2:$N$401='03_Dashboard'!$H$6))*(('03_Dashboard'!$J$6="")+('02_Trade_Log'!$C$2:$C$401>='03_Dashboard'!$J$6))*(('03_Dashboard'!$L$6="")+('02_Trade_Log'!$C$2:$C$401<='03_Dashboard'!$L$6)))*(('02_Trade_Log'!$E$2:$E$401=A7))*('02_Trade_Log'!$AK$2:$AK$401="BE")) | F7: =IF(B7=0,"—",C7/B7) | G7: =SUMPRODUCT((('02_Trade_Log'!$AK$2:$AK$401<>"Open")*('02_Trade_Log'!$C$2:$C$401<>"")*(('03_Dashboard'!$D$6="All")+('02_Trade_Log'!$B$2:$B$401='03_Dashboard'!$D$6))*(('03_Dashboard'!$F$6="All")+('02_Trade_Log'!$G$2:$G$401='03_Dashboard'!$F$6))*(('03_Dashboard'!$H$6="All")+('02_Trade_Log'!$N$2:$N$401='03_Dashboard'!$H$6))*(('03_Dashboard'!$J$6="")+('02_Trade_Log'!$C$2:$C$401>='03_Dashboard'!$J$6))*(('03_Dashboard'!$L$6="")+('02_Trade_Log'!$C$2:$C$401<='03_Dashboard'!$L$6)))*(('02_Trade_Log'!$E$2:$E$401=A7))*('02_Trade_Log'!$AJ$2:$AJ$401)) | H7: =IF(SUMPRODUCT((('02_Trade_Log'!$AK$2:$AK$401<>"Open")*('02_Trade_Log'!$C$2:$C$401<>"")*(('03_Dashboard'!$D$6="All")+('02_Trade_Log'!$B$2:$B$401='03_Dashboard'!$D$6))*(('03_Dashboard'!$F$6="All")+('02_Trade_Log'!$G$2:$G$401='03_Dashboard'!$F$6))*(('03_Dashboard'!$H$6="All")+('02_Trade_Log'!$N$2:$N$401='03_Dashboard'!$H$6))*(('03_Dashboard'!$J$6="")+('02_Trade_Log'!$C$2:$C$401>='03_Dashboard'!$J$6))*(('03_Dashboard'!$L$6="")+('02_Trade_Log'!$C$2:$C$401<='03_Dashboard'!$L$6)))*(('02_Trade_Log'!$E$2:$E$401=A7))*('02_Trade_Log'!$AJ$2:$AJ$401<0)*('02_Trade_Log'!$AJ$2:$AJ$401))=0,IF(SUMPRODUCT((('02_Trade_Log'!$AK$2:$AK$401<>"Open")*('02_Trade_Log'!$C$2:$C$401<>"")*(('03_Dashboard'!$D$6="All")+('02_Trade_Log'!$B$2:$B$401='03_Dashboard'!$D$6))*(('03_Dashboard'!$F$6="All")+('02_Trade_Log'!$G$2:$G$401='03_Dashboard'!$F$6))*(('03_Dashboard'!$H$6="All")+('02_Trade_Log'!$N$2:$N$401='03_Dashboard'!$H$6))*(('03_Dashboard'!$J$6="")+('02_Trade_Log'!$C$2:$C$401>='03_Dashboard'!$J$6))*(('03_Dashboard'!$L$6="")+('02_Trade_Log'!$C$2:$C$401<='03_Dashboard'!$L$6)))*(('02_Trade_Log'!$E$2:$E$401=A7))*('02_Trade_Log'!$AJ$2:$AJ$401>0)*('02_Trade_Log'!$AJ$2:$AJ$401))>0,"∞","—"),SUMPRODUCT((('02_Trade_Log'!$AK$2:$AK$401<>"Open")*('02_Trade_Log'!$C$2:$C$401<>"")*(('03_Dashboard'!$D$6="All")+('02_Trade_Log'!$B$2:$B$401='03_Dashboard'!$D$6))*(('03_Dashboard'!$F$6="All")+('02_Trade_Log'!$G$2:$G$401='03_Dashboard'!$F$6))*(('03_Dashboard'!$H$6="All")+('02_Trade_Log'!$N$2:$N$401='03_Dashboard'!$H$6))*(('03_Dashboard'!$J$6="")+('02_Trade_Log'!$C$2:$C$401>='03_Dashboard'!$J$6))*(('03_Dashboard'!$L$6="")+('02_Trade_Log'!$C$2:$C$401<='03_Dashboard'!$L$6)))*(('02_Trade_Log'!$E$2:$E$401=A7))*('02_Trade_Log'!$AJ$2:$AJ$401>0)*('02_Trade_Log'!$AJ$2:$AJ$401))/ABS(SUMPRODUCT((('02_Trade_Log'!$AK$2:$AK$401<>"Open")*('02_Trade_Log'!$C$2:$C$401<>"")*(('03_Dashboard'!$D$6="All")+('02_Trade_Log'!$B$2:$B$401='03_Dashboard'!$D$6))*(('03_Dashboard'!$F$6="All")+('02_Trade_Log'!$G$2:$G$401='03_Dashboard'!$F$6))*(('03_Dashboard'!$H$6="All")+('02_Trade_Log'!$N$2:$N$401='03_Dashboard'!$H$6))*(('03_Dashboard'!$J$6="")+('02_Trade_Log'!$C$2:$C$401>='03_Dashboard'!$J$6))*(('03_Dashboard'!$L$6="")+('02_Trade_Log'!$C$2:$C$401<='03_Dashboard'!$L$6)))*(('02_Trade_Log'!$E$2:$E$401=A7))*('02_Trade_Log'!$AJ$2:$AJ$401<0)*('02_Trade_Log'!$AJ$2:$AJ$401)))) | I7: =IF(C7=0,"—",SUMPRODUCT((('02_Trade_Log'!$AK$2:$AK$401<>"Open")*('02_Trade_Log'!$C$2:$C$401<>"")*(('03_Dashboard'!$D$6="All")+('02_Trade_Log'!$B$2:$B$401='03_Dashboard'!$D$6))*(('03_Dashboard'!$F$6="All")+('02_Trade_Log'!$G$2:$G$401='03_Dashboard'!$F$6))*(('03_Dashboard'!$H$6="All")+('02_Trade_Log'!$N$2:$N$401='03_Dashboard'!$H$6))*(('03_Dashboard'!$J$6="")+('02_Trade_Log'!$C$2:$C$401>='03_Dashboard'!$J$6))*(('03_Dashboard'!$L$6="")+('02_Trade_Log'!$C$2:$C$401<='03_Dashboard'!$L$6)))*(('02_Trade_Log'!$E$2:$E$401=A7))*('02_Trade_Log'!$AK$2:$AK$401="Win")*('02_Trade_Log'!$AJ$2:$AJ$401))/C7) | J7: =IF(D7=0,"—",SUMPRODUCT((('02_Trade_Log'!$AK$2:$AK$401<>"Open")*('02_Trade_Log'!$C$2:$C$401<>"")*(('03_Dashboard'!$D$6="All")+('02_Trade_Log'!$B$2:$B$401='03_Dashboard'!$D$6))*(('03_Dashboard'!$F$6="All")+('02_Trade_Log'!$G$2:$G$401='03_Dashboard'!$F$6))*(('03_Dashboard'!$H$6="All")+('02_Trade_Log'!$N$2:$N$401='03_Dashboard'!$H$6))*(('03_Dashboard'!$J$6="")+('02_Trade_Log'!$C$2:$C$401>='03_Dashboard'!$J$6))*(('03_Dashboard'!$L$6="")+('02_Trade_Log'!$C$2:$C$401<='03_Dashboard'!$L$6)))*(('02_Trade_Log'!$E$2:$E$401=A7))*('02_Trade_Log'!$AK$2:$AK$401="Loss")*('02_Trade_Log'!$AJ$2:$AJ$401))/D7) | K7: =IF(B7=0,"—",G7/B7) | N7: =A40 | O7: =G40 | P7: =IF(ISNUMBER(F40),F40,0)
A8: AUDCAD | B8: =SUMPRODUCT((('02_Trade_Log'!$AK$2:$AK$401<>"Open")*('02_Trade_Log'!$C$2:$C$401<>"")*(('03_Dashboard'!$D$6="All")+('02_Trade_Log'!$B$2:$B$401='03_Dashboard'!$D$6))*(('03_Dashboard'!$F$6="All")+('02_Trade_Log'!$G$2:$G$401='03_Dashboard'!$F$6))*(('03_Dashboard'!$H$6="All")+('02_Trade_Log'!$N$2:$N$401='03_Dashboard'!$H$6))*(('03_Dashboard'!$J$6="")+('02_Trade_Log'!$C$2:$C$401>='03_Dashboard'!$J$6))*(('03_Dashboard'!$L$6="")+('02_Trade_Log'!$C$2:$C$401<='03_Dashboard'!$L$6)))*(('02_Trade_Log'!$E$2:$E$401=A8))) | C8: =SUMPRODUCT((('02_Trade_Log'!$AK$2:$AK$401<>"Open")*('02_Trade_Log'!$C$2:$C$401<>"")*(('03_Dashboard'!$D$6="All")+('02_Trade_Log'!$B$2:$B$401='03_Dashboard'!$D$6))*(('03_Dashboard'!$F$6="All")+('02_Trade_Log'!$G$2:$G$401='03_Dashboard'!$F$6))*(('03_Dashboard'!$H$6="All")+('02_Trade_Log'!$N$2:$N$401='03_Dashboard'!$H$6))*(('03_Dashboard'!$J$6="")+('02_Trade_Log'!$C$2:$C$401>='03_Dashboard'!$J$6))*(('03_Dashboard'!$L$6="")+('02_Trade_Log'!$C$2:$C$401<='03_Dashboard'!$L$6)))*(('02_Trade_Log'!$E$2:$E$401=A8))*('02_Trade_Log'!$AK$2:$AK$401="Win")) | D8: =SUMPRODUCT((('02_Trade_Log'!$AK$2:$AK$401<>"Open")*('02_Trade_Log'!$C$2:$C$401<>"")*(('03_Dashboard'!$D$6="All")+('02_Trade_Log'!$B$2:$B$401='03_Dashboard'!$D$6))*(('03_Dashboard'!$F$6="All")+('02_Trade_Log'!$G$2:$G$401='03_Dashboard'!$F$6))*(('03_Dashboard'!$H$6="All")+('02_Trade_Log'!$N$2:$N$401='03_Dashboard'!$H$6))*(('03_Dashboard'!$J$6="")+('02_Trade_Log'!$C$2:$C$401>='03_Dashboard'!$J$6))*(('03_Dashboard'!$L$6="")+('02_Trade_Log'!$C$2:$C$401<='03_Dashboard'!$L$6)))*(('02_Trade_Log'!$E$2:$E$401=A8))*('02_Trade_Log'!$AK$2:$AK$401="Loss")) | E8: =SUMPRODUCT((('02_Trade_Log'!$AK$2:$AK$401<>"Open")*('02_Trade_Log'!$C$2:$C$401<>"")*(('03_Dashboard'!$D$6="All")+('02_Trade_Log'!$B$2:$B$401='03_Dashboard'!$D$6))*(('03_Dashboard'!$F$6="All")+('02_Trade_Log'!$G$2:$G$401='03_Dashboard'!$F$6))*(('03_Dashboard'!$H$6="All")+('02_Trade_Log'!$N$2:$N$401='03_Dashboard'!$H$6))*(('03_Dashboard'!$J$6="")+('02_Trade_Log'!$C$2:$C$401>='03_Dashboard'!$J$6))*(('03_Dashboard'!$L$6="")+('02_Trade_Log'!$C$2:$C$401<='03_Dashboard'!$L$6)))*(('02_Trade_Log'!$E$2:$E$401=A8))*('02_Trade_Log'!$AK$2:$AK$401="BE")) | F8: =IF(B8=0,"—",C8/B8) | G8: =SUMPRODUCT((('02_Trade_Log'!$AK$2:$AK$401<>"Open")*('02_Trade_Log'!$C$2:$C$401<>"")*(('03_Dashboard'!$D$6="All")+('02_Trade_Log'!$B$2:$B$401='03_Dashboard'!$D$6))*(('03_Dashboard'!$F$6="All")+('02_Trade_Log'!$G$2:$G$401='03_Dashboard'!$F$6))*(('03_Dashboard'!$H$6="All")+('02_Trade_Log'!$N$2:$N$401='03_Dashboard'!$H$6))*(('03_Dashboard'!$J$6="")+('02_Trade_Log'!$C$2:$C$401>='03_Dashboard'!$J$6))*(('03_Dashboard'!$L$6="")+('02_Trade_Log'!$C$2:$C$401<='03_Dashboard'!$L$6)))*(('02_Trade_Log'!$E$2:$E$401=A8))*('02_Trade_Log'!$AJ$2:$AJ$401)) | H8: =IF(SUMPRODUCT((('02_Trade_Log'!$AK$2:$AK$401<>"Open")*('02_Trade_Log'!$C$2:$C$401<>"")*(('03_Dashboard'!$D$6="All")+('02_Trade_Log'!$B$2:$B$401='03_Dashboard'!$D$6))*(('03_Dashboard'!$F$6="All")+('02_Trade_Log'!$G$2:$G$401='03_Dashboard'!$F$6))*(('03_Dashboard'!$H$6="All")+('02_Trade_Log'!$N$2:$N$401='03_Dashboard'!$H$6))*(('03_Dashboard'!$J$6="")+('02_Trade_Log'!$C$2:$C$401>='03_Dashboard'!$J$6))*(('03_Dashboard'!$L$6="")+('02_Trade_Log'!$C$2:$C$401<='03_Dashboard'!$L$6)))*(('02_Trade_Log'!$E$2:$E$401=A8))*('02_Trade_Log'!$AJ$2:$AJ$401<0)*('02_Trade_Log'!$AJ$2:$AJ$401))=0,IF(SUMPRODUCT((('02_Trade_Log'!$AK$2:$AK$401<>"Open")*('02_Trade_Log'!$C$2:$C$401<>"")*(('03_Dashboard'!$D$6="All")+('02_Trade_Log'!$B$2:$B$401='03_Dashboard'!$D$6))*(('03_Dashboard'!$F$6="All")+('02_Trade_Log'!$G$2:$G$401='03_Dashboard'!$F$6))*(('03_Dashboard'!$H$6="All")+('02_Trade_Log'!$N$2:$N$401='03_Dashboard'!$H$6))*(('03_Dashboard'!$J$6="")+('02_Trade_Log'!$C$2:$C$401>='03_Dashboard'!$J$6))*(('03_Dashboard'!$L$6="")+('02_Trade_Log'!$C$2:$C$401<='03_Dashboard'!$L$6)))*(('02_Trade_Log'!$E$2:$E$401=A8))*('02_Trade_Log'!$AJ$2:$AJ$401>0)*('02_Trade_Log'!$AJ$2:$AJ$401))>0,"∞","—"),SUMPRODUCT((('02_Trade_Log'!$AK$2:$AK$401<>"Open")*('02_Trade_Log'!$C$2:$C$401<>"")*(('03_Dashboard'!$D$6="All")+('02_Trade_Log'!$B$2:$B$401='03_Dashboard'!$D$6))*(('03_Dashboard'!$F$6="All")+('02_Trade_Log'!$G$2:$G$401='03_Dashboard'!$F$6))*(('03_Dashboard'!$H$6="All")+('02_Trade_Log'!$N$2:$N$401='03_Dashboard'!$H$6))*(('03_Dashboard'!$J$6="")+('02_Trade_Log'!$C$2:$C$401>='03_Dashboard'!$J$6))*(('03_Dashboard'!$L$6="")+('02_Trade_Log'!$C$2:$C$401<='03_Dashboard'!$L$6)))*(('02_Trade_Log'!$E$2:$E$401=A8))*('02_Trade_Log'!$AJ$2:$AJ$401>0)*('02_Trade_Log'!$AJ$2:$AJ$401))/ABS(SUMPRODUCT((('02_Trade_Log'!$AK$2:$AK$401<>"Open")*('02_Trade_Log'!$C$2:$C$401<>"")*(('03_Dashboard'!$D$6="All")+('02_Trade_Log'!$B$2:$B$401='03_Dashboard'!$D$6))*(('03_Dashboard'!$F$6="All")+('02_Trade_Log'!$G$2:$G$401='03_Dashboard'!$F$6))*(('03_Dashboard'!$H$6="All")+('02_Trade_Log'!$N$2:$N$401='03_Dashboard'!$H$6))*(('03_Dashboard'!$J$6="")+('02_Trade_Log'!$C$2:$C$401>='03_Dashboard'!$J$6))*(('03_Dashboard'!$L$6="")+('02_Trade_Log'!$C$2:$C$401<='03_Dashboard'!$L$6)))*(('02_Trade_Log'!$E$2:$E$401=A8))*('02_Trade_Log'!$AJ$2:$AJ$401<0)*('02_Trade_Log'!$AJ$2:$AJ$401)))) | I8: =IF(C8=0,"—",SUMPRODUCT((('02_Trade_Log'!$AK$2:$AK$401<>"Open")*('02_Trade_Log'!$C$2:$C$401<>"")*(('03_Dashboard'!$D$6="All")+('02_Trade_Log'!$B$2:$B$401='03_Dashboard'!$D$6))*(('03_Dashboard'!$F$6="All")+('02_Trade_Log'!$G$2:$G$401='03_Dashboard'!$F$6))*(('03_Dashboard'!$H$6="All")+('02_Trade_Log'!$N$2:$N$401='03_Dashboard'!$H$6))*(('03_Dashboard'!$J$6="")+('02_Trade_Log'!$C$2:$C$401>='03_Dashboard'!$J$6))*(('03_Dashboard'!$L$6="")+('02_Trade_Log'!$C$2:$C$401<='03_Dashboard'!$L$6)))*(('02_Trade_Log'!$E$2:$E$401=A8))*('02_Trade_Log'!$AK$2:$AK$401="Win")*('02_Trade_Log'!$AJ$2:$AJ$401))/C8) | J8: =IF(D8=0,"—",SUMPRODUCT((('02_Trade_Log'!$AK$2:$AK$401<>"Open")*('02_Trade_Log'!$C$2:$C$401<>"")*(('03_Dashboard'!$D$6="All")+('02_Trade_Log'!$B$2:$B$401='03_Dashboard'!$D$6))*(('03_Dashboard'!$F$6="All")+('02_Trade_Log'!$G$2:$G$401='03_Dashboard'!$F$6))*(('03_Dashboard'!$H$6="All")+('02_Trade_Log'!$N$2:$N$401='03_Dashboard'!$H$6))*(('03_Dashboard'!$J$6="")+('02_Trade_Log'!$C$2:$C$401>='03_Dashboard'!$J$6))*(('03_Dashboard'!$L$6="")+('02_Trade_Log'!$C$2:$C$401<='03_Dashboard'!$L$6)))*(('02_Trade_Log'!$E$2:$E$401=A8))*('02_Trade_Log'!$AK$2:$AK$401="Loss")*('02_Trade_Log'!$AJ$2:$AJ$401))/D8) | K8: =IF(B8=0,"—",G8/B8) | N8: =A41 | O8: =G41 | P8: =IF(ISNUMBER(F41),F41,0)
A9: AUDUSD | B9: =SUMPRODUCT((('02_Trade_Log'!$AK$2:$AK$401<>"Open")*('02_Trade_Log'!$C$2:$C$401<>"")*(('03_Dashboard'!$D$6="All")+('02_Trade_Log'!$B$2:$B$401='03_Dashboard'!$D$6))*(('03_Dashboard'!$F$6="All")+('02_Trade_Log'!$G$2:$G$401='03_Dashboard'!$F$6))*(('03_Dashboard'!$H$6="All")+('02_Trade_Log'!$N$2:$N$401='03_Dashboard'!$H$6))*(('03_Dashboard'!$J$6="")+('02_Trade_Log'!$C$2:$C$401>='03_Dashboard'!$J$6))*(('03_Dashboard'!$L$6="")+('02_Trade_Log'!$C$2:$C$401<='03_Dashboard'!$L$6)))*(('02_Trade_Log'!$E$2:$E$401=A9))) | C9: =SUMPRODUCT((('02_Trade_Log'!$AK$2:$AK$401<>"Open")*('02_Trade_Log'!$C$2:$C$401<>"")*(('03_Dashboard'!$D$6="All")+('02_Trade_Log'!$B$2:$B$401='03_Dashboard'!$D$6))*(('03_Dashboard'!$F$6="All")+('02_Trade_Log'!$G$2:$G$401='03_Dashboard'!$F$6))*(('03_Dashboard'!$H$6="All")+('02_Trade_Log'!$N$2:$N$401='03_Dashboard'!$H$6))*(('03_Dashboard'!$J$6="")+('02_Trade_Log'!$C$2:$C$401>='03_Dashboard'!$J$6))*(('03_Dashboard'!$L$6="")+('02_Trade_Log'!$C$2:$C$401<='03_Dashboard'!$L$6)))*(('02_Trade_Log'!$E$2:$E$401=A9))*('02_Trade_Log'!$AK$2:$AK$401="Win")) | D9: =SUMPRODUCT((('02_Trade_Log'!$AK$2:$AK$401<>"Open")*('02_Trade_Log'!$C$2:$C$401<>"")*(('03_Dashboard'!$D$6="All")+('02_Trade_Log'!$B$2:$B$401='03_Dashboard'!$D$6))*(('03_Dashboard'!$F$6="All")+('02_Trade_Log'!$G$2:$G$401='03_Dashboard'!$F$6))*(('03_Dashboard'!$H$6="All")+('02_Trade_Log'!$N$2:$N$401='03_Dashboard'!$H$6))*(('03_Dashboard'!$J$6="")+('02_Trade_Log'!$C$2:$C$401>='03_Dashboard'!$J$6))*(('03_Dashboard'!$L$6="")+('02_Trade_Log'!$C$2:$C$401<='03_Dashboard'!$L$6)))*(('02_Trade_Log'!$E$2:$E$401=A9))*('02_Trade_Log'!$AK$2:$AK$401="Loss")) | E9: =SUMPRODUCT((('02_Trade_Log'!$AK$2:$AK$401<>"Open")*('02_Trade_Log'!$C$2:$C$401<>"")*(('03_Dashboard'!$D$6="All")+('02_Trade_Log'!$B$2:$B$401='03_Dashboard'!$D$6))*(('03_Dashboard'!$F$6="All")+('02_Trade_Log'!$G$2:$G$401='03_Dashboard'!$F$6))*(('03_Dashboard'!$H$6="All")+('02_Trade_Log'!$N$2:$N$401='03_Dashboard'!$H$6))*(('03_Dashboard'!$J$6="")+('02_Trade_Log'!$C$2:$C$401>='03_Dashboard'!$J$6))*(('03_Dashboard'!$L$6="")+('02_Trade_Log'!$C$2:$C$401<='03_Dashboard'!$L$6)))*(('02_Trade_Log'!$E$2:$E$401=A9))*('02_Trade_Log'!$AK$2:$AK$401="BE")) | F9: =IF(B9=0,"—",C9/B9) | G9: =SUMPRODUCT((('02_Trade_Log'!$AK$2:$AK$401<>"Open")*('02_Trade_Log'!$C$2:$C$401<>"")*(('03_Dashboard'!$D$6="All")+('02_Trade_Log'!$B$2:$B$401='03_Dashboard'!$D$6))*(('03_Dashboard'!$F$6="All")+('02_Trade_Log'!$G$2:$G$401='03_Dashboard'!$F$6))*(('03_Dashboard'!$H$6="All")+('02_Trade_Log'!$N$2:$N$401='03_Dashboard'!$H$6))*(('03_Dashboard'!$J$6="")+('02_Trade_Log'!$C$2:$C$401>='03_Dashboard'!$J$6))*(('03_Dashboard'!$L$6="")+('02_Trade_Log'!$C$2:$C$401<='03_Dashboard'!$L$6)))*(('02_Trade_Log'!$E$2:$E$401=A9))*('02_Trade_Log'!$AJ$2:$AJ$401)) | H9: =IF(SUMPRODUCT((('02_Trade_Log'!$AK$2:$AK$401<>"Open")*('02_Trade_Log'!$C$2:$C$401<>"")*(('03_Dashboard'!$D$6="All")+('02_Trade_Log'!$B$2:$B$401='03_Dashboard'!$D$6))*(('03_Dashboard'!$F$6="All")+('02_Trade_Log'!$G$2:$G$401='03_Dashboard'!$F$6))*(('03_Dashboard'!$H$6="All")+('02_Trade_Log'!$N$2:$N$401='03_Dashboard'!$H$6))*(('03_Dashboard'!$J$6="")+('02_Trade_Log'!$C$2:$C$401>='03_Dashboard'!$J$6))*(('03_Dashboard'!$L$6="")+('02_Trade_Log'!$C$2:$C$401<='03_Dashboard'!$L$6)))*(('02_Trade_Log'!$E$2:$E$401=A9))*('02_Trade_Log'!$AJ$2:$AJ$401<0)*('02_Trade_Log'!$AJ$2:$AJ$401))=0,IF(SUMPRODUCT((('02_Trade_Log'!$AK$2:$AK$401<>"Open")*('02_Trade_Log'!$C$2:$C$401<>"")*(('03_Dashboard'!$D$6="All")+('02_Trade_Log'!$B$2:$B$401='03_Dashboard'!$D$6))*(('03_Dashboard'!$F$6="All")+('02_Trade_Log'!$G$2:$G$401='03_Dashboard'!$F$6))*(('03_Dashboard'!$H$6="All")+('02_Trade_Log'!$N$2:$N$401='03_Dashboard'!$H$6))*(('03_Dashboard'!$J$6="")+('02_Trade_Log'!$C$2:$C$401>='03_Dashboard'!$J$6))*(('03_Dashboard'!$L$6="")+('02_Trade_Log'!$C$2:$C$401<='03_Dashboard'!$L$6)))*(('02_Trade_Log'!$E$2:$E$401=A9))*('02_Trade_Log'!$AJ$2:$AJ$401>0)*('02_Trade_Log'!$AJ$2:$AJ$401))>0,"∞","—"),SUMPRODUCT((('02_Trade_Log'!$AK$2:$AK$401<>"Open")*('02_Trade_Log'!$C$2:$C$401<>"")*(('03_Dashboard'!$D$6="All")+('02_Trade_Log'!$B$2:$B$401='03_Dashboard'!$D$6))*(('03_Dashboard'!$F$6="All")+('02_Trade_Log'!$G$2:$G$401='03_Dashboard'!$F$6))*(('03_Dashboard'!$H$6="All")+('02_Trade_Log'!$N$2:$N$401='03_Dashboard'!$H$6))*(('03_Dashboard'!$J$6="")+('02_Trade_Log'!$C$2:$C$401>='03_Dashboard'!$J$6))*(('03_Dashboard'!$L$6="")+('02_Trade_Log'!$C$2:$C$401<='03_Dashboard'!$L$6)))*(('02_Trade_Log'!$E$2:$E$401=A9))*('02_Trade_Log'!$AJ$2:$AJ$401>0)*('02_Trade_Log'!$AJ$2:$AJ$401))/ABS(SUMPRODUCT((('02_Trade_Log'!$AK$2:$AK$401<>"Open")*('02_Trade_Log'!$C$2:$C$401<>"")*(('03_Dashboard'!$D$6="All")+('02_Trade_Log'!$B$2:$B$401='03_Dashboard'!$D$6))*(('03_Dashboard'!$F$6="All")+('02_Trade_Log'!$G$2:$G$401='03_Dashboard'!$F$6))*(('03_Dashboard'!$H$6="All")+('02_Trade_Log'!$N$2:$N$401='03_Dashboard'!$H$6))*(('03_Dashboard'!$J$6="")+('02_Trade_Log'!$C$2:$C$401>='03_Dashboard'!$J$6))*(('03_Dashboard'!$L$6="")+('02_Trade_Log'!$C$2:$C$401<='03_Dashboard'!$L$6)))*(('02_Trade_Log'!$E$2:$E$401=A9))*('02_Trade_Log'!$AJ$2:$AJ$401<0)*('02_Trade_Log'!$AJ$2:$AJ$401)))) | I9: =IF(C9=0,"—",SUMPRODUCT((('02_Trade_Log'!$AK$2:$AK$401<>"Open")*('02_Trade_Log'!$C$2:$C$401<>"")*(('03_Dashboard'!$D$6="All")+('02_Trade_Log'!$B$2:$B$401='03_Dashboard'!$D$6))*(('03_Dashboard'!$F$6="All")+('02_Trade_Log'!$G$2:$G$401='03_Dashboard'!$F$6))*(('03_Dashboard'!$H$6="All")+('02_Trade_Log'!$N$2:$N$401='03_Dashboard'!$H$6))*(('03_Dashboard'!$J$6="")+('02_Trade_Log'!$C$2:$C$401>='03_Dashboard'!$J$6))*(('03_Dashboard'!$L$6="")+('02_Trade_Log'!$C$2:$C$401<='03_Dashboard'!$L$6)))*(('02_Trade_Log'!$E$2:$E$401=A9))*('02_Trade_Log'!$AK$2:$AK$401="Win")*('02_Trade_Log'!$AJ$2:$AJ$401))/C9) | J9: =IF(D9=0,"—",SUMPRODUCT((('02_Trade_Log'!$AK$2:$AK$401<>"Open")*('02_Trade_Log'!$C$2:$C$401<>"")*(('03_Dashboard'!$D$6="All")+('02_Trade_Log'!$B$2:$B$401='03_Dashboard'!$D$6))*(('03_Dashboard'!$F$6="All")+('02_Trade_Log'!$G$2:$G$401='03_Dashboard'!$F$6))*(('03_Dashboard'!$H$6="All")+('02_Trade_Log'!$N$2:$N$401='03_Dashboard'!$H$6))*(('03_Dashboard'!$J$6="")+('02_Trade_Log'!$C$2:$C$401>='03_Dashboard'!$J$6))*(('03_Dashboard'!$L$6="")+('02_Trade_Log'!$C$2:$C$401<='03_Dashboard'!$L$6)))*(('02_Trade_Log'!$E$2:$E$401=A9))*('02_Trade_Log'!$AK$2:$AK$401="Loss")*('02_Trade_Log'!$AJ$2:$AJ$401))/D9) | K9: =IF(B9=0,"—",G9/B9) | N9: =A42 | O9: =G42 | P9: =IF(ISNUMBER(F42),F42,0)
A10: AUDNZD | B10: =SUMPRODUCT((('02_Trade_Log'!$AK$2:$AK$401<>"Open")*('02_Trade_Log'!$C$2:$C$401<>"")*(('03_Dashboard'!$D$6="All")+('02_Trade_Log'!$B$2:$B$401='03_Dashboard'!$D$6))*(('03_Dashboard'!$F$6="All")+('02_Trade_Log'!$G$2:$G$401='03_Dashboard'!$F$6))*(('03_Dashboard'!$H$6="All")+('02_Trade_Log'!$N$2:$N$401='03_Dashboard'!$H$6))*(('03_Dashboard'!$J$6="")+('02_Trade_Log'!$C$2:$C$401>='03_Dashboard'!$J$6))*(('03_Dashboard'!$L$6="")+('02_Trade_Log'!$C$2:$C$401<='03_Dashboard'!$L$6)))*(('02_Trade_Log'!$E$2:$E$401=A10))) | C10: =SUMPRODUCT((('02_Trade_Log'!$AK$2:$AK$401<>"Open")*('02_Trade_Log'!$C$2:$C$401<>"")*(('03_Dashboard'!$D$6="All")+('02_Trade_Log'!$B$2:$B$401='03_Dashboard'!$D$6))*(('03_Dashboard'!$F$6="All")+('02_Trade_Log'!$G$2:$G$401='03_Dashboard'!$F$6))*(('03_Dashboard'!$H$6="All")+('02_Trade_Log'!$N$2:$N$401='03_Dashboard'!$H$6))*(('03_Dashboard'!$J$6="")+('02_Trade_Log'!$C$2:$C$401>='03_Dashboard'!$J$6))*(('03_Dashboard'!$L$6="")+('02_Trade_Log'!$C$2:$C$401<='03_Dashboard'!$L$6)))*(('02_Trade_Log'!$E$2:$E$401=A10))*('02_Trade_Log'!$AK$2:$AK$401="Win")) | D10: =SUMPRODUCT((('02_Trade_Log'!$AK$2:$AK$401<>"Open")*('02_Trade_Log'!$C$2:$C$401<>"")*(('03_Dashboard'!$D$6="All")+('02_Trade_Log'!$B$2:$B$401='03_Dashboard'!$D$6))*(('03_Dashboard'!$F$6="All")+('02_Trade_Log'!$G$2:$G$401='03_Dashboard'!$F$6))*(('03_Dashboard'!$H$6="All")+('02_Trade_Log'!$N$2:$N$401='03_Dashboard'!$H$6))*(('03_Dashboard'!$J$6="")+('02_Trade_Log'!$C$2:$C$401>='03_Dashboard'!$J$6))*(('03_Dashboard'!$L$6="")+('02_Trade_Log'!$C$2:$C$401<='03_Dashboard'!$L$6)))*(('02_Trade_Log'!$E$2:$E$401=A10))*('02_Trade_Log'!$AK$2:$AK$401="Loss")) | E10: =SUMPRODUCT((('02_Trade_Log'!$AK$2:$AK$401<>"Open")*('02_Trade_Log'!$C$2:$C$401<>"")*(('03_Dashboard'!$D$6="All")+('02_Trade_Log'!$B$2:$B$401='03_Dashboard'!$D$6))*(('03_Dashboard'!$F$6="All")+('02_Trade_Log'!$G$2:$G$401='03_Dashboard'!$F$6))*(('03_Dashboard'!$H$6="All")+('02_Trade_Log'!$N$2:$N$401='03_Dashboard'!$H$6))*(('03_Dashboard'!$J$6="")+('02_Trade_Log'!$C$2:$C$401>='03_Dashboard'!$J$6))*(('03_Dashboard'!$L$6="")+('02_Trade_Log'!$C$2:$C$401<='03_Dashboard'!$L$6)))*(('02_Trade_Log'!$E$2:$E$401=A10))*('02_Trade_Log'!$AK$2:$AK$401="BE")) | F10: =IF(B10=0,"—",C10/B10) | G10: =SUMPRODUCT((('02_Trade_Log'!$AK$2:$AK$401<>"Open")*('02_Trade_Log'!$C$2:$C$401<>"")*(('03_Dashboard'!$D$6="All")+('02_Trade_Log'!$B$2:$B$401='03_Dashboard'!$D$6))*(('03_Dashboard'!$F$6="All")+('02_Trade_Log'!$G$2:$G$401='03_Dashboard'!$F$6))*(('03_Dashboard'!$H$6="All")+('02_Trade_Log'!$N$2:$N$401='03_Dashboard'!$H$6))*(('03_Dashboard'!$J$6="")+('02_Trade_Log'!$C$2:$C$401>='03_Dashboard'!$J$6))*(('03_Dashboard'!$L$6="")+('02_Trade_Log'!$C$2:$C$401<='03_Dashboard'!$L$6)))*(('02_Trade_Log'!$E$2:$E$401=A10))*('02_Trade_Log'!$AJ$2:$AJ$401)) | H10: =IF(SUMPRODUCT((('02_Trade_Log'!$AK$2:$AK$401<>"Open")*('02_Trade_Log'!$C$2:$C$401<>"")*(('03_Dashboard'!$D$6="All")+('02_Trade_Log'!$B$2:$B$401='03_Dashboard'!$D$6))*(('03_Dashboard'!$F$6="All")+('02_Trade_Log'!$G$2:$G$401='03_Dashboard'!$F$6))*(('03_Dashboard'!$H$6="All")+('02_Trade_Log'!$N$2:$N$401='03_Dashboard'!$H$6))*(('03_Dashboard'!$J$6="")+('02_Trade_Log'!$C$2:$C$401>='03_Dashboard'!$J$6))*(('03_Dashboard'!$L$6="")+('02_Trade_Log'!$C$2:$C$401<='03_Dashboard'!$L$6)))*(('02_Trade_Log'!$E$2:$E$401=A10))*('02_Trade_Log'!$AJ$2:$AJ$401<0)*('02_Trade_Log'!$AJ$2:$AJ$401))=0,IF(SUMPRODUCT((('02_Trade_Log'!$AK$2:$AK$401<>"Open")*('02_Trade_Log'!$C$2:$C$401<>"")*(('03_Dashboard'!$D$6="All")+('02_Trade_Log'!$B$2:$B$401='03_Dashboard'!$D$6))*(('03_Dashboard'!$F$6="All")+('02_Trade_Log'!$G$2:$G$401='03_Dashboard'!$F$6))*(('03_Dashboard'!$H$6="All")+('02_Trade_Log'!$N$2:$N$401='03_Dashboard'!$H$6))*(('03_Dashboard'!$J$6="")+('02_Trade_Log'!$C$2:$C$401>='03_Dashboard'!$J$6))*(('03_Dashboard'!$L$6="")+('02_Trade_Log'!$C$2:$C$401<='03_Dashboard'!$L$6)))*(('02_Trade_Log'!$E$2:$E$401=A10))*('02_Trade_Log'!$AJ$2:$AJ$401>0)*('02_Trade_Log'!$AJ$2:$AJ$401))>0,"∞","—"),SUMPRODUCT((('02_Trade_Log'!$AK$2:$AK$401<>"Open")*('02_Trade_Log'!$C$2:$C$401<>"")*(('03_Dashboard'!$D$6="All")+('02_Trade_Log'!$B$2:$B$401='03_Dashboard'!$D$6))*(('03_Dashboard'!$F$6="All")+('02_Trade_Log'!$G$2:$G$401='03_Dashboard'!$F$6))*(('03_Dashboard'!$H$6="All")+('02_Trade_Log'!$N$2:$N$401='03_Dashboard'!$H$6))*(('03_Dashboard'!$J$6="")+('02_Trade_Log'!$C$2:$C$401>='03_Dashboard'!$J$6))*(('03_Dashboard'!$L$6="")+('02_Trade_Log'!$C$2:$C$401<='03_Dashboard'!$L$6)))*(('02_Trade_Log'!$E$2:$E$401=A10))*('02_Trade_Log'!$AJ$2:$AJ$401>0)*('02_Trade_Log'!$AJ$2:$AJ$401))/ABS(SUMPRODUCT((('02_Trade_Log'!$AK$2:$AK$401<>"Open")*('02_Trade_Log'!$C$2:$C$401<>"")*(('03_Dashboard'!$D$6="All")+('02_Trade_Log'!$B$2:$B$401='03_Dashboard'!$D$6))*(('03_Dashboard'!$F$6="All")+('02_Trade_Log'!$G$2:$G$401='03_Dashboard'!$F$6))*(('03_Dashboard'!$H$6="All")+('02_Trade_Log'!$N$2:$N$401='03_Dashboard'!$H$6))*(('03_Dashboard'!$J$6="")+('02_Trade_Log'!$C$2:$C$401>='03_Dashboard'!$J$6))*(('03_Dashboard'!$L$6="")+('02_Trade_Log'!$C$2:$C$401<='03_Dashboard'!$L$6)))*(('02_Trade_Log'!$E$2:$E$401=A10))*('02_Trade_Log'!$AJ$2:$AJ$401<0)*('02_Trade_Log'!$AJ$2:$AJ$401)))) | I10: =IF(C10=0,"—",SUMPRODUCT((('02_Trade_Log'!$AK$2:$AK$401<>"Open")*('02_Trade_Log'!$C$2:$C$401<>"")*(('03_Dashboard'!$D$6="All")+('02_Trade_Log'!$B$2:$B$401='03_Dashboard'!$D$6))*(('03_Dashboard'!$F$6="All")+('02_Trade_Log'!$G$2:$G$401='03_Dashboard'!$F$6))*(('03_Dashboard'!$H$6="All")+('02_Trade_Log'!$N$2:$N$401='03_Dashboard'!$H$6))*(('03_Dashboard'!$J$6="")+('02_Trade_Log'!$C$2:$C$401>='03_Dashboard'!$J$6))*(('03_Dashboard'!$L$6="")+('02_Trade_Log'!$C$2:$C$401<='03_Dashboard'!$L$6)))*(('02_Trade_Log'!$E$2:$E$401=A10))*('02_Trade_Log'!$AK$2:$AK$401="Win")*('02_Trade_Log'!$AJ$2:$AJ$401))/C10) | J10: =IF(D10=0,"—",SUMPRODUCT((('02_Trade_Log'!$AK$2:$AK$401<>"Open")*('02_Trade_Log'!$C$2:$C$401<>"")*(('03_Dashboard'!$D$6="All")+('02_Trade_Log'!$B$2:$B$401='03_Dashboard'!$D$6))*(('03_Dashboard'!$F$6="All")+('02_Trade_Log'!$G$2:$G$401='03_Dashboard'!$F$6))*(('03_Dashboard'!$H$6="All")+('02_Trade_Log'!$N$2:$N$401='03_Dashboard'!$H$6))*(('03_Dashboard'!$J$6="")+('02_Trade_Log'!$C$2:$C$401>='03_Dashboard'!$J$6))*(('03_Dashboard'!$L$6="")+('02_Trade_Log'!$C$2:$C$401<='03_Dashboard'!$L$6)))*(('02_Trade_Log'!$E$2:$E$401=A10))*('02_Trade_Log'!$AK$2:$AK$401="Loss")*('02_Trade_Log'!$AJ$2:$AJ$401))/D10) | K10: =IF(B10=0,"—",G10/B10) | N10: =A43 | O10: =G43 | P10: =IF(ISNUMBER(F43),F43,0)
